
Loading dataset...
Loaded data : 93389
batch_size = 128
learning rate = 0.0001
train_size = 74711
test_size = 18678
Data load complete!
Initializing model....
Traceback (most recent call last):
  File "Dilated_conv_vae_main.py", line 117, in <module>
    state = init_state(model,
  File "Dilated_conv_vae_main.py", line 35, in init_state
    params = model.init({'params': key}, jnp.ones(x_shape), key)
  File "/usr/local/lib/python3.8/dist-packages/jax/_src/traceback_util.py", line 162, in reraise_with_filtered_traceback
    return fun(*args, **kwargs)
  File "/usr/local/lib/python3.8/dist-packages/flax/linen/module.py", line 1273, in init
    _, v_out = self.init_with_output(
  File "/usr/local/lib/python3.8/dist-packages/jax/_src/traceback_util.py", line 162, in reraise_with_filtered_traceback
    return fun(*args, **kwargs)
  File "/usr/local/lib/python3.8/dist-packages/flax/linen/module.py", line 1229, in init_with_output
    return init_with_output(
  File "/usr/local/lib/python3.8/dist-packages/flax/core/scope.py", line 897, in wrapper
    return apply(fn, mutable=mutable, flags=init_flags)({}, *args, rngs=rngs,
  File "/usr/local/lib/python3.8/dist-packages/flax/core/scope.py", line 865, in wrapper
    y = fn(root, *args, **kwargs)
  File "/usr/local/lib/python3.8/dist-packages/flax/linen/module.py", line 1647, in scope_fn
    return fn(module.clone(parent=scope), *args, **kwargs)
  File "/usr/local/lib/python3.8/dist-packages/flax/linen/module.py", line 361, in wrapped_module_method
    return self._call_wrapped_method(fun, args, kwargs)
  File "/usr/local/lib/python3.8/dist-packages/flax/linen/module.py", line 657, in _call_wrapped_method
    y = fun(self, *args, **kwargs)
  File "/home/anthonypark6904/module/dilated_Conv_vae_model.py", line 122, in __call__
    mean, logvar = self.encoder(x)
  File "/usr/local/lib/python3.8/dist-packages/flax/linen/module.py", line 361, in wrapped_module_method
    return self._call_wrapped_method(fun, args, kwargs)
  File "/usr/local/lib/python3.8/dist-packages/flax/linen/module.py", line 657, in _call_wrapped_method
    y = fun(self, *args, **kwargs)
  File "/home/anthonypark6904/module/dilated_Conv_vae_model.py", line 15, in __call__
    x = nn.Conv(512, kernel_size=(1,1),  strides=[1,1], kernel_dilation=2, padding='same')(x)
  File "/usr/local/lib/python3.8/dist-packages/flax/linen/module.py", line 361, in wrapped_module_method
    return self._call_wrapped_method(fun, args, kwargs)
  File "/usr/local/lib/python3.8/dist-packages/flax/linen/module.py", line 657, in _call_wrapped_method
    y = fun(self, *args, **kwargs)
  File "/usr/local/lib/python3.8/dist-packages/flax/linen/linear.py", line 435, in __call__
    y = lax.conv_general_dilated(
  File "/usr/local/lib/python3.8/dist-packages/jax/_src/lax/convolution.py", line 157, in conv_general_dilated
    return conv_general_dilated_p.bind(
  File "/usr/local/lib/python3.8/dist-packages/jax/core.py", line 324, in bind
    return self.bind_with_trace(find_top_trace(args), args, params)
  File "/usr/local/lib/python3.8/dist-packages/jax/core.py", line 327, in bind_with_trace
    out = trace.process_primitive(self, map(trace.full_raise, args), params)
  File "/usr/local/lib/python3.8/dist-packages/jax/core.py", line 684, in process_primitive
    return primitive.impl(*tracers, **params)
  File "/usr/local/lib/python3.8/dist-packages/jax/_src/dispatch.py", line 101, in apply_primitive
    return compiled_fun(*args)
  File "/usr/local/lib/python3.8/dist-packages/jax/_src/dispatch.py", line 176, in <lambda>
    return lambda *args, **kw: compiled(*args, **kw)[0]
  File "/usr/local/lib/python3.8/dist-packages/jax/_src/dispatch.py", line 755, in _execute_compiled
    out_flat = compiled.execute(in_flat)
jax._src.traceback_util.UnfilteredStackTrace: jaxlib.xla_extension.XlaRuntimeError: RESOURCE_EXHAUSTED: Failed to allocate request for 21.98GiB (23605542912B) on device ordinal 0
The stack trace below excludes JAX-internal frames.
The preceding is the original exception that occurred, unmodified.
--------------------
The above exception was the direct cause of the following exception:
Traceback (most recent call last):
  File "Dilated_conv_vae_main.py", line 117, in <module>
    state = init_state(model,
  File "Dilated_conv_vae_main.py", line 35, in init_state
    params = model.init({'params': key}, jnp.ones(x_shape), key)
  File "/home/anthonypark6904/module/dilated_Conv_vae_model.py", line 122, in __call__
    mean, logvar = self.encoder(x)
  File "/home/anthonypark6904/module/dilated_Conv_vae_model.py", line 15, in __call__
    x = nn.Conv(512, kernel_size=(1,1),  strides=[1,1], kernel_dilation=2, padding='same')(x)
  File "/usr/local/lib/python3.8/dist-packages/flax/linen/linear.py", line 435, in __call__
    y = lax.conv_general_dilated(
jaxlib.xla_extension.XlaRuntimeError: RESOURCE_EXHAUSTED: Failed to allocate request for 21.98GiB (23605542912B) on device ordinal 0
Traceback (most recent call last):
  File "Dilated_conv_vae_main.py", line 117, in <module>
    state = init_state(model,
  File "Dilated_conv_vae_main.py", line 35, in init_state
    params = model.init({'params': key}, jnp.ones(x_shape), key)
  File "/usr/local/lib/python3.8/dist-packages/jax/_src/traceback_util.py", line 162, in reraise_with_filtered_traceback
    return fun(*args, **kwargs)
  File "/usr/local/lib/python3.8/dist-packages/flax/linen/module.py", line 1273, in init
    _, v_out = self.init_with_output(
  File "/usr/local/lib/python3.8/dist-packages/jax/_src/traceback_util.py", line 162, in reraise_with_filtered_traceback
    return fun(*args, **kwargs)
  File "/usr/local/lib/python3.8/dist-packages/flax/linen/module.py", line 1229, in init_with_output
    return init_with_output(
  File "/usr/local/lib/python3.8/dist-packages/flax/core/scope.py", line 897, in wrapper
    return apply(fn, mutable=mutable, flags=init_flags)({}, *args, rngs=rngs,
  File "/usr/local/lib/python3.8/dist-packages/flax/core/scope.py", line 865, in wrapper
    y = fn(root, *args, **kwargs)
  File "/usr/local/lib/python3.8/dist-packages/flax/linen/module.py", line 1647, in scope_fn
    return fn(module.clone(parent=scope), *args, **kwargs)
  File "/usr/local/lib/python3.8/dist-packages/flax/linen/module.py", line 361, in wrapped_module_method
    return self._call_wrapped_method(fun, args, kwargs)
  File "/usr/local/lib/python3.8/dist-packages/flax/linen/module.py", line 657, in _call_wrapped_method
    y = fun(self, *args, **kwargs)
  File "/home/anthonypark6904/module/dilated_Conv_vae_model.py", line 122, in __call__
    mean, logvar = self.encoder(x)
  File "/usr/local/lib/python3.8/dist-packages/flax/linen/module.py", line 361, in wrapped_module_method
    return self._call_wrapped_method(fun, args, kwargs)
  File "/usr/local/lib/python3.8/dist-packages/flax/linen/module.py", line 657, in _call_wrapped_method
    y = fun(self, *args, **kwargs)
  File "/home/anthonypark6904/module/dilated_Conv_vae_model.py", line 15, in __call__
    x = nn.Conv(512, kernel_size=(1,1),  strides=[1,1], kernel_dilation=2, padding='same')(x)
  File "/usr/local/lib/python3.8/dist-packages/flax/linen/module.py", line 361, in wrapped_module_method
    return self._call_wrapped_method(fun, args, kwargs)
  File "/usr/local/lib/python3.8/dist-packages/flax/linen/module.py", line 657, in _call_wrapped_method
    y = fun(self, *args, **kwargs)
  File "/usr/local/lib/python3.8/dist-packages/flax/linen/linear.py", line 435, in __call__
    y = lax.conv_general_dilated(
  File "/usr/local/lib/python3.8/dist-packages/jax/_src/lax/convolution.py", line 157, in conv_general_dilated
    return conv_general_dilated_p.bind(
  File "/usr/local/lib/python3.8/dist-packages/jax/core.py", line 324, in bind
    return self.bind_with_trace(find_top_trace(args), args, params)
  File "/usr/local/lib/python3.8/dist-packages/jax/core.py", line 327, in bind_with_trace
    out = trace.process_primitive(self, map(trace.full_raise, args), params)
  File "/usr/local/lib/python3.8/dist-packages/jax/core.py", line 684, in process_primitive
    return primitive.impl(*tracers, **params)
  File "/usr/local/lib/python3.8/dist-packages/jax/_src/dispatch.py", line 101, in apply_primitive
    return compiled_fun(*args)
  File "/usr/local/lib/python3.8/dist-packages/jax/_src/dispatch.py", line 176, in <lambda>
    return lambda *args, **kw: compiled(*args, **kw)[0]
  File "/usr/local/lib/python3.8/dist-packages/jax/_src/dispatch.py", line 755, in _execute_compiled
    out_flat = compiled.execute(in_flat)
jax._src.traceback_util.UnfilteredStackTrace: jaxlib.xla_extension.XlaRuntimeError: RESOURCE_EXHAUSTED: Failed to allocate request for 21.98GiB (23605542912B) on device ordinal 0
The stack trace below excludes JAX-internal frames.
The preceding is the original exception that occurred, unmodified.
--------------------
The above exception was the direct cause of the following exception:
Traceback (most recent call last):
  File "Dilated_conv_vae_main.py", line 117, in <module>
    state = init_state(model,
  File "Dilated_conv_vae_main.py", line 35, in init_state
    params = model.init({'params': key}, jnp.ones(x_shape), key)
  File "/home/anthonypark6904/module/dilated_Conv_vae_model.py", line 122, in __call__
    mean, logvar = self.encoder(x)
  File "/home/anthonypark6904/module/dilated_Conv_vae_model.py", line 15, in __call__
    x = nn.Conv(512, kernel_size=(1,1),  strides=[1,1], kernel_dilation=2, padding='same')(x)
  File "/usr/local/lib/python3.8/dist-packages/flax/linen/linear.py", line 435, in __call__
    y = lax.conv_general_dilated(
jaxlib.xla_extension.XlaRuntimeError: RESOURCE_EXHAUSTED: Failed to allocate request for 21.98GiB (23605542912B) on device ordinal 0