
Epoch 1






































epoch 1 - average loss - train : 0.018000001087784767, test : 0.0170000009238719945
Pre train complete!
Linear evalutaion step.
Traceback (most recent call last):
  File "main.py", line 282, in <module>
    test_loss, test_accuarcy = linear_eval_step(linear_state, test_x, rng)
  File "/usr/local/lib/python3.8/dist-packages/jax/_src/traceback_util.py", line 162, in reraise_with_filtered_traceback
    return fun(*args, **kwargs)
  File "/usr/local/lib/python3.8/dist-packages/jax/_src/api.py", line 527, in cache_miss
    out_flat = xla.xla_call(
  File "/usr/local/lib/python3.8/dist-packages/jax/core.py", line 1937, in bind
    return call_bind(self, fun, *args, **params)
  File "/usr/local/lib/python3.8/dist-packages/jax/core.py", line 1953, in call_bind
    outs = top_trace.process_call(primitive, fun_, tracers, params)
  File "/usr/local/lib/python3.8/dist-packages/jax/core.py", line 687, in process_call
    return primitive.impl(f, *tracers, **params)
  File "/usr/local/lib/python3.8/dist-packages/jax/_src/dispatch.py", line 208, in _xla_call_impl
    compiled_fun = xla_callable(fun, device, backend, name, donated_invars,
  File "/usr/local/lib/python3.8/dist-packages/jax/linear_util.py", line 295, in memoized_fun
    ans = call(fun, *args)
  File "/usr/local/lib/python3.8/dist-packages/jax/_src/dispatch.py", line 257, in _xla_callable_uncached
    return lower_xla_callable(fun, device, backend, name, donated_invars, False,
  File "/usr/local/lib/python3.8/dist-packages/jax/_src/profiler.py", line 294, in wrapper
    return func(*args, **kwargs)
  File "/usr/local/lib/python3.8/dist-packages/jax/_src/dispatch.py", line 302, in lower_xla_callable
    jaxpr, out_type, consts = pe.trace_to_jaxpr_final2(
  File "/usr/local/lib/python3.8/dist-packages/jax/_src/profiler.py", line 294, in wrapper
    return func(*args, **kwargs)
  File "/usr/local/lib/python3.8/dist-packages/jax/interpreters/partial_eval.py", line 2188, in trace_to_jaxpr_final2
    jaxpr, out_type, consts = trace_to_subjaxpr_dynamic2(fun, main, debug_info)
  File "/usr/local/lib/python3.8/dist-packages/jax/interpreters/partial_eval.py", line 2138, in trace_to_subjaxpr_dynamic2
    ans = fun.call_wrapped(*in_tracers_)
  File "/usr/local/lib/python3.8/dist-packages/jax/linear_util.py", line 168, in call_wrapped
    ans = self.f(*args, **dict(self.params, **kwargs))
jax._src.traceback_util.UnfilteredStackTrace: TypeError: linear_eval_step() missing 2 required positional arguments: 'x' and 'y'
The stack trace below excludes JAX-internal frames.
The preceding is the original exception that occurred, unmodified.
--------------------
The above exception was the direct cause of the following exception:
Traceback (most recent call last):
  File "main.py", line 282, in <module>
    test_loss, test_accuarcy = linear_eval_step(linear_state, test_x, rng)
TypeError: linear_eval_step() missing 2 required positional arguments: 'x' and 'y'
Traceback (most recent call last):
  File "main.py", line 282, in <module>
    test_loss, test_accuarcy = linear_eval_step(linear_state, test_x, rng)
  File "/usr/local/lib/python3.8/dist-packages/jax/_src/traceback_util.py", line 162, in reraise_with_filtered_traceback
    return fun(*args, **kwargs)
  File "/usr/local/lib/python3.8/dist-packages/jax/_src/api.py", line 527, in cache_miss
    out_flat = xla.xla_call(
  File "/usr/local/lib/python3.8/dist-packages/jax/core.py", line 1937, in bind
    return call_bind(self, fun, *args, **params)
  File "/usr/local/lib/python3.8/dist-packages/jax/core.py", line 1953, in call_bind
    outs = top_trace.process_call(primitive, fun_, tracers, params)
  File "/usr/local/lib/python3.8/dist-packages/jax/core.py", line 687, in process_call
    return primitive.impl(f, *tracers, **params)
  File "/usr/local/lib/python3.8/dist-packages/jax/_src/dispatch.py", line 208, in _xla_call_impl
    compiled_fun = xla_callable(fun, device, backend, name, donated_invars,
  File "/usr/local/lib/python3.8/dist-packages/jax/linear_util.py", line 295, in memoized_fun
    ans = call(fun, *args)
  File "/usr/local/lib/python3.8/dist-packages/jax/_src/dispatch.py", line 257, in _xla_callable_uncached
    return lower_xla_callable(fun, device, backend, name, donated_invars, False,
  File "/usr/local/lib/python3.8/dist-packages/jax/_src/profiler.py", line 294, in wrapper
    return func(*args, **kwargs)
  File "/usr/local/lib/python3.8/dist-packages/jax/_src/dispatch.py", line 302, in lower_xla_callable
    jaxpr, out_type, consts = pe.trace_to_jaxpr_final2(
  File "/usr/local/lib/python3.8/dist-packages/jax/_src/profiler.py", line 294, in wrapper
    return func(*args, **kwargs)
  File "/usr/local/lib/python3.8/dist-packages/jax/interpreters/partial_eval.py", line 2188, in trace_to_jaxpr_final2
    jaxpr, out_type, consts = trace_to_subjaxpr_dynamic2(fun, main, debug_info)
  File "/usr/local/lib/python3.8/dist-packages/jax/interpreters/partial_eval.py", line 2138, in trace_to_subjaxpr_dynamic2
    ans = fun.call_wrapped(*in_tracers_)
  File "/usr/local/lib/python3.8/dist-packages/jax/linear_util.py", line 168, in call_wrapped
    ans = self.f(*args, **dict(self.params, **kwargs))
jax._src.traceback_util.UnfilteredStackTrace: TypeError: linear_eval_step() missing 2 required positional arguments: 'x' and 'y'
The stack trace below excludes JAX-internal frames.
The preceding is the original exception that occurred, unmodified.
--------------------
The above exception was the direct cause of the following exception:
Traceback (most recent call last):
  File "main.py", line 282, in <module>
    test_loss, test_accuarcy = linear_eval_step(linear_state, test_x, rng)
TypeError: linear_eval_step() missing 2 required positional arguments: 'x' and 'y'